Workbook

Sheet Instrucciones
B1: Plantilla de testing — instrucciones para juniors
B4: Antes de empezar
B5: 1. Lee la hoja "Plan de testing" para saber qué área te toca esta semana.
B6: 2. Antes de reportar un bug, busca en la hoja "Bugs" si ya está reportado. Si lo está, NO crees uno nuevo: añade tu nombre en la columna "Reportado también por" para que sepamos cuánta gente lo ve.
B7: 3. Para reportar, ve a la hoja "Bugs" y rellena UNA fila por bug. No mezcles dos bugs en la misma fila.
B8: 4. Las propuestas de mejora NO son bugs. Van en la hoja "Propuestas de mejora". Si lo mezclas, contaminas la cola de los devs y nos retrasas.
B10: Qué es bug y qué no es
B11: • Bug: el sistema hace algo distinto de lo que debería. Ejemplo: "al crear paciente con email vacío, la pantalla se queda en blanco" → BUG.
B12: • No es bug: el sistema funciona, pero crees que se podría hacer mejor. Ejemplo: "el botón de guardar debería ser más visible" → PROPUESTA DE MEJORA.
B13: • Duda de uso: el sistema funciona, pero no entiendes cómo se usa. Pregunta antes de reportar; no es bug.
B15: Cómo reportar bien (las 3 cosas que importan)
B16: 1. PASOS PARA REPRODUCIR: tan claros que cualquiera pueda seguirlos. Ejemplo: "1) Login como admin. 2) Ir a Pacientes. 3) Crear paciente con nombre vacío. 4) Pulsar Guardar."
... B42: • Cuando el PM marque tu bug como "Arreglado", revisa que efectivamente está arreglado y cámbialo a "Verificado" o reábrelo si no lo está.

Sheet Bugs
A1: 👇 Una fila por bug. Columna A se autocompleta. Borra la fila de ejemplo (fila 3, en gris) cuando empieces a usarla.
A2: ID | B2: Fecha | C2: Tester (código) | D2: Feature | E2: Pasos para reproducir | F2: Qué pasó | G2: Qué esperaba | H2: Captura (link) | I2: Severidad (tester) | J2: Reportado también por | K2: Severidad (PM) | L2: Estado | M2: Duplicado de | N2: Asignado a | O2: Notas internas (PM/dev) | P2: Fecha arreglo
A3: =IF(C2="","","BUG-"&TEXT(ROW()-1,"000")) -> BUG-002 | B3: 2026-05-13 | C3: JUN01 | D3: Sales orders/Facturación | E3: 1) Login como admin. 2) Crear cita para paciente con mutua. 3) Marcar consulta como efectuada. 4) Ir a facturación. | F3: La factura suma dos veces el importe del servicio: aparece 120€ cuando deberían ser 60€. | G3: El importe del servicio debería aparecer una sola vez: 60€. | H3: https://drive.google.com/file/... | I3: Bloqueante | K3: Bloqueante | L3: Arreglado | N3: Dip | O3: Confirmado, mismo bug que el de la reunión del lunes. Test de regresión requerido.
A4: =IF(C3="","","BUG-"&TEXT(ROW()-1,"000")) -> BUG-003 | B4: 46155 | C4: DMT | D4: CRM | E4: 1) Login como admin. 2) Acceder al CRM. 3) Entrar en el apartado de Mail Templates. | F4: La página se queda en blanco y deja de funcionar. | G4: Acceder al apartado de mail templates. | H4: Screenshot_20260514_083951.png | I4: Bloqueante | J4: JUN03, JUN05, Randú, JZO | K4: Bloqueante
A5: =IF(C4="","","BUG-"&TEXT(ROW()-1,"000")) -> BUG-004 | B5: 46155 | C5: DMT | D5: CRM | E5: 1) Login como admin. 2) Acceder al CRM. 3) Entrar en el apartado de Invoices dentro de Marketplace. | F5: La página se queda en blanco y deja de funcionar. | G5: Acceder al apartado de Invoices. | H5: Screenshot_20260514_085235.png | I5: Bloqueante | J5: JUN05, Randú | K5: Menor
A6: =IF(C5="","","BUG-"&TEXT(ROW()-1,"000")) -> BUG-005 | B6: 46156 | C6: DMT | D6: CRM | E6: 1) Login como admin. 2) Acceder a cualquier apartado del CRM. | F6: Los apartados de la barra superior de notificaciones aparecen con un indicador de mensaje/s no leido/s aunque todos estén marcados como leido. | G6: Que al marcar como leido todos los mensajes, desaparezca el indicador. | H6: Screenshot_20260514_085622.png | I6: Menor | K6: Bloqueante | L6: En arreglo
A7: =IF(C6="","","BUG-"&TEXT(ROW()-1,"000")) -> BUG-006 | B7: 46156 | C7: DMT | D7: CRM | E7: 1) Login como admin. 2) Crear un paciente en creación rápida. | F7: Al presionar la tecla ESC o clickar fuera de la ventana, esta realiza una animación de cerrado, pero no se llega a cerrar. | G7: Cerrar la ventana emergente. | H7: Screenshot_20260514_090456.png | I7: Menor | K7: No es bug | L7: No es bug
A8: =IF(C7="","","BUG-"&TEXT(ROW()-1,"000")) -> BUG-007 | B8: 46156 | C8: DMT | D8: CRM | E8: 1) Login como admin. 2) Acceder al CRM. 3) Editar un lead sin cambiar ningun dato. 4) Guardar cambios. | F8: Aunque no haya ningún cambio al editar el lead, se puede guardar los cambios como si hubiera alguno y aparece la ventana de cambios guardados. Tambén pasa en otros módulos del CRM. | G8: No permitir guardar cambios si no hay ninguno realizado | H8: Screenshot_20260514_091734.png | I8: Menor | K8: Menor | L8: Verificado
A9: =IF(C8="","","BUG-"&TEXT(ROW()-1,"000")) -> BUG-008 | B9: 46156 | C9: DMT | D9: CRM | E9: 1) Login como admin. 2) Acceder al CRM. 3) Bajar el rango del lead. | F9: El rango de un lead no tiene límite, por lo que puede llegar a ser negativo. | G9: No permitir bajar el rango de un lead por debajo de cero. | H9: Screenshot_20260514_092655.png | I9: Menor | K9: No es bug | L9: No es bug
A10: =IF(C9="","","BUG-"&TEXT(ROW()-1,"000")) -> BUG-009 | B10: 46156 | C10: DMT | D10: CRM | E10: 1) Login como admin. 2) Acceder al apartado de contactos del CRM. 3) Elegir contacto. | F10: Cualuier usuario tiene acceso a los contactos creados de cualquier otro usuario. | G10: Solo visualizar los contactos del mismo usuario. | H10: Screenshot_20260514_093635.png | I10: Grave | K10: Diferido | L10: Diferido
A11: =IF(C10="","","BUG-"&TEXT(ROW()-1,"000")) -> BUG-010 | B11: 46156 | C11: Randú | D11: CRM | E11: 1) Login como admin. 2) Acceder al CRM. 3) Elegir opción de Dashboard de Marketplace. | F11: No redirige al usuario a ninguna pagina y en general no hace nada. | G11: Que me redirija a un Dashboard. | H11: https://drive.google.com/file/d/1qqBVZUej6lS8O71n8ZLcrwVh4ghafLVO/view?usp=drive_link | I11: Menor | K11: Menor | L11: Verificado
A12: =IF(C11="","","BUG-"&TEXT(ROW()-1,"000")) -> BUG-011 | B12: 46156 | C12: DMT | D12: CRM | E12: 1) Login como admin. 2) Crear una lista. 3) Añadir leads a la lista. 4) Añadir distintos leads a la lista. | F12: Al añadir leads a una lista, reemplazan a los anteriores, en vez de añadirlos. | G12: Añadir a los leads junto a los anteriores. | H12: Screenshot_20260514_094457.png | I12: Grave | K12: Bloqueante | L12: En arreglo
A13: =IF(C12="","","BUG-"&TEXT(ROW()-1,"000")) -> BUG-012 | B13: 46156 | C13: DMT | D13: CRM | E13: 1) Login como admin. 2) Crear una lista de empresas | F13: Es imposible añadir empresas a una lista de empresas, puesto que en ningún apartado se pueden ver o modificar empresas en el CRM. | G13: Encontrar forma de añadir empresas a la lista | H13: Screenshot_20260514_095759.png | I13: Grave | K13: Bloqueante | L13: En arreglo
A14: =IF(C13="","","BUG-"&TEXT(ROW()-1,"000")) -> BUG-013 | B14: 46156 | C14: DMT | D14: CRM | E14: 1) Login como admin. 2) Acceder al apartado de label. 3) Añadir flitros. 4) Resetear filtros. | F14: Los filtros no se resetean a no ser que se cambie de apartado. | G14: Que los filtros se reinicien y se muestren los labels sin filtros. | H14: Screenshot_20260514_100704.png | I14: Menor | K14: Bloqueante | L14: En arreglo
A15: =IF(C14="","","BUG-"&TEXT(ROW()-1,"000")) -> BUG-014 | B15: 46156 | C15: DMT | D15: CRM | E15: 1) Login como admin. 2) Acceder al apartado Activity Process. 3) Crear proceso. 4) Cerrar sin guardar. | F15: La página no se cierra. | G15: La página se debería cerrar. | H15: Screenshot_20260514_100835.png | I15: Menor
A16: =IF(C15="","","BUG-"&TEXT(ROW()-1,"000")) -> BUG-015 | B16: 46156 | C16: 46177 | D16: CRM | E16: 1)Login como admin 2)Acceder al apartado de mercado 3)Crear producto 4)añadir | F16: Cuando queremos añadir una nueva tienda nos dice que tenemos el acceso restringido | G16: Que cree el producto correctamente | H16: https://drive.google.com/file/d/1lmedZyT55g_dk8IBSurOILoN2A-bTnph/view?usp=sharing | I16: Menor | K16: No es bug | L16: No es bug
A17: =IF(C16="","","BUG-"&TEXT(ROW()-1,"000")) -> BUG-016 | B17: 46156 | C17: 46177 | D17: CRM | E17: 1) Login como admin 2) Acceder al apartado Finance 3) Acceder al apartado órdenes 4) Crear nueva Órden | F17: La página se queda cargando los datos de la orden | G17: Cargar la interfaz para añadir la orden y poder añadir una nueva sin ningún error | H17: https://drive.google.com/file/d/1tGW5Ffw0ZowRGWD0rd3FQjz9tE8LoC74/view?usp=sharing | I17: Bloqueante | J17: JUN13, DMT | K17: Menor | L17: Diferido
A18: BUG-017 | B18: 46156 | C18: 46180 | D18: Crear paciente | E18: 1)Login como admin 2)Acceder al apartado clinical Service 3) Acceder al apartado Paciente | F18: No permite crear un nuevo paciente si no creas primero una clínica | G18: Tener opciones de clínicas o permitir añadir después | H18: https://drive.google.com/file/d/1br5eCdTbDq_lK0ZQQifxY4c_6RAumYKl/view?usp=drive_link | I18: Bloqueante | K18: No es bug | L18: No es bug
A19: BUG-018 | B19: 46160 | C19: DMT | D19: CRM | E19: 1) Login como admin. 2) Acceder al apartado de oportunidades del CRM. 3) Crear una oportunidad. 4) Bajar el porcentaje de promesa. | F19: El porcentaje de promesa no tiene límite, por lo que puede llegar a ser negativo o mayor de 100. | G19: Ya que el porcentaje de promesa no debería poder ser negativo, limitar el porcentaje a números positivos entre 0 y 100. | H19: Screenshot_20260518_084155.png | I19: Menor | K19: Menor | L19: Diferido
A20: =IF(C19="","","BUG-"&TEXT(ROW()-1,"000")) -> BUG-019 | B20: 46160 | C20: DMT | D20: CRM | E20: 1) Login como admin. 2) Acceder al apartado de notas del CRM. 3) Crear una nota. | F20: En el apartado de notas no aparece la opción de mandar notificación al usuario, mientras que en el apartado individual de Lead, Tarea o Contacto, sí que lo permite. | G20: Añadir la casilla de marcar notificación. | H20: Screenshot_20260518_085300.png | I20: Menor | K20: Menor | L20: En revisión
A21: =IF(C20="","","BUG-"&TEXT(ROW()-1,"000")) -> BUG-020 | B21: 46160 | C21: DMT | D21: CRM | E21: 1) Login como admin. 2) Acceder a los datos de un Lead. 3) Añadir CV. | F21: El botón de añadir CV es el mismo que el del usuario, por lo que pone "Add your CV". | G21: Cambiar el botón por "Add CV". | H21: Screenshot_20260518_085924.png | I21: Menor | K21: Menor | L21: Diferido
A22: =IF(C21="","","BUG-"&TEXT(ROW()-1,"000")) -> BUG-021 | B22: 46160 | C22: DMT | D22: CRM | E22: 1) Login como admin. 2) Acceder al apartado de notas del CRM. 3) Presionar los 3 puntos para editar nota. | F22: Los datos de título, descripción y marcar como privado no cargan correctamente y hace falta cargar la nota desde Nota Existente. | G22: Cargar los datos correctamente. | H22: Screenshot_20260518_090511.png | I22: Grave | J22: Randú
A23: =IF(C22="","","BUG-"&TEXT(ROW()-1,"000")) -> BUG-022 | B23: 46160 | C23: DMT | D23: CRM | E23: 1) Login como admin. 2) Acceder a los datos de un Lead. 3) Editar nota. 4) Editar nota existente. 5) Editar nota existente. | F23: Se puede editar nota recursivamente de forma infinita. | G23: Si ya estás editando la nota, que no aparezca el botón de editar nota. | H23: Screenshot_20260518_090829.png | I23: Menor
A24: =IF(C23="","","BUG-"&TEXT(ROW()-1,"000")) -> BUG-023 | B24: 46160 | C24: DMT | D24: CRM | E24: 1) Login como admin. 2) Acceder al apartado de notas del CRM. 3) Borrar una o varias notas. | F24: No es posible borrar ninguna nota, debido a que el botón Delete no funciona. | G24: El botón Delete debe permitir borrar la o las notas. | H24: Screenshot_20260518_091310.png | I24: Grave
A25: =IF(C24="","","BUG-"&TEXT(ROW()-1,"000")) -> BUG-024 | B25: 46160 | C25: DMT | D25: Otra | E25: 1) Login como admin. 2) Acceder al apartado de challenges. 3) Añadir un challenge de cualqier tipo. | F25: La página crashea y se queda en blanco. | G25: Acceder a la creación de un challenge. | H25: Screenshot_20260518_091658.png | I25: Bloqueante
A26: =IF(C25="","","BUG-"&TEXT(ROW()-1,"000")) -> BUG-025 | B26: 46160 | C26: DMT | D26: Otra | E26: 1) Login como admin. 2) Acceder al dashboard de Marketplace. | F26: El botón de Dashboad de Marketplace lleva a la página en la que te encuentras. | G26: Acceder al Dashboard de Marketplace. | H26: Screenshot_20260518_092218.png | I26: Grave
A27: =IF(C26="","","BUG-"&TEXT(ROW()-1,"000")) -> BUG-026 | B27: 46160 | C27: DMT | D27: Otra | E27: 1) Login como admin. 2) Acceder al apartado Customer Pricing de marketplace. | F27: La página muestra los productos guardados por otros usuarios. A pesar de no poder crear uno, cualquier usuario puede editar o borrar los productos de otros. | G27: No tener acceso a los productos guardados por otros usuarios. | H27: Screenshot_20260518_093135.png | I27: Grave
A28: =IF(C27="","","BUG-"&TEXT(ROW()-1,"000")) -> BUG-027 | B28: 46160 | C28: DMT | D28: Otra | E28: 1) Login como admin. 2) Acceder al apartado Supplier Pricing de marketplace. | F28: La página muestra los productos guardados por otros usuarios. A pesar de no poder crear uno, cualquier usuario puede editar o borrar los productos de otros. | G28: No tener acceso a los productos guardados por otros usuarios. | H28: Screenshot_20260518_093539.png | I28: Grave
A29: =IF(C28="","","BUG-"&TEXT(ROW()-1,"000")) -> BUG-028 | B29: 46160 | C29: Randú | D29: Otra | E29: 1) Login como admin. 2) Acceder al CRM. 3) Seleccionar un paciente o varios en Clinical service. 4) Elejir la opción de share with doctor de Actions. 5) precionar share sin elegir doctor. | F29: Se bloquea la página y se pone en blanco. | G29: Un aviso de 'no se puede enviar sin un doctor'. | H29: https://drive.google.com/file/d/1hHLwfY8w4Iy469VwfLYvxlAC2GV43_7h/view?usp=drive_link | I29: Bloqueante
A30: =IF(C29="","","BUG-"&TEXT(ROW()-1,"000")) -> BUG-029 | B30: 46160 | C30: JZO | D30: Otra | E30: 1) Login como admin. 2) Acceder al Marketplace. 3) Acceder al apartado tablero | F30: Al seleccionar botón no ejecuta la acción de entrar al tablero. | G30: Poder acceder a la sección del tablero | H30: https://drive.google.com/file/d/1KI-IuNjs34QyMsv-DbwFZnflQJFTTutu/view?usp=sharing | I30: Menor
A31: =IF(C30="","","BUG-"&TEXT(ROW()-1,"000")) -> BUG-030 | B31: 46160 | C31: JZO | D31: Otra | E31: 1) Login como admin. 2) Acceder al Analityc Dashboard. 3) Acceder a Clinic A / Clinic B / Clinic C | F31: Al querer acceder a los supuestos dashboards de las clínicas, te devuelve directamente a la sección de Dashboard principal | G31: Acceder a cada sección de clinica y poder ver sus supuestos tableros | H31: https://drive.google.com/file/d/1XkzQ6F-ZeoTUnoxeDgHVaJhw6ft0N2LX/view?usp=drive_link | I31: Bloqueante
A32: =IF(C31="","","BUG-"&TEXT(ROW()-1,"000")) -> BUG-031 | B32: 46160 | C32: JZO | D32: Otra | E32: 1) Login como admin. 2) Acceder al Faq. 3) Añadir Fag. | F32: El botón de 'Suggested by AI' no ejecuta ninguna función | G32: Que ejecutase alguna acción en la que se pueda ver la funcionalidad de la IA. | H32: https://drive.google.com/file/d/1gGBxNpr6ryk-MDXa1bpHdO5rriUvsG4r/view?usp=drive_link | I32: Menor | J32: JUN06,
A33: =IF(C32="","","BUG-"&TEXT(ROW()-1,"000")) -> BUG-032 | B33: 46160 | C33: 46179 | D33: Otra | E33: 1) Login como admin. 2) Acceder al Clinical Service. 3) Acceder a Recetas. 4) Agregar nueva receta | F33: En el apartado "Other Instructions", el subapartado "Attachments", no carga el documento o imagén subida | G33: Debería cargar la imagén o documento subido y guardarse en el formulario para luego subirlo | H33: https://drive.google.com/file/d/1RwEqdkCnkHkd90w7_YfS87k4UO09d6sS/view?usp=drive_link | I33: Menor
A34: =IF(C33="","","BUG-"&TEXT(ROW()-1,"000")) -> BUG-033 | B34: 46160 | C34: JZO | D34: Otra | E34: 1) Login como admin. 2) Acceder a Finance. 3) Acceder a Subscription. 4) Boton action. 5) Boton Add Label | F34: Los botones "Add Tag" y "Remove Tag" no cumplen con ninguna función | G34: Que pueda añadir tags dandole al botón y poder eliminar los tags que selecciono. | H34: https://drive.google.com/file/d/1_Kw_XXR8lOB4Aco9KS3C0YDALi9L0GSw/view?usp=drive_link | I34: Menor
A35: =IF(C34="","","BUG-"&TEXT(ROW()-1,"000")) -> BUG-034 | B35: 46160 | C35: 46179 | D35: Otra | E35: 1) Login como admin. 2) Acceder al Clinical Service. 3) Acceder a Productos. 4) Agregar nueva producto | F35: En el apartado "Advanced Information", el subapartado "Product Image", carga infinitamente la imagén o documento subido. | G35: Debería cargar la imagén o documento subido y guardarse en el formulario para luego subirlo. (Se completa el formulario) | H35: https://drive.google.com/file/d/15IvnQg9E8RxEAim6FfUZBGql_jlH5LL_/view?usp=drive_link | I35: Menor
A36: =IF(C35="","","BUG-"&TEXT(ROW()-1,"000")) -> BUG-035 | B36: 46160 | C36: RGP | D36: Otra | E36: 1) Login como admin. 2) Acceder a Dashboard/Ecosystem Dashboard. 3) Directory. 4) Filtrar los Ecosystems | F36: El filtrado saca que hay 3 ecosistemas cuando son 2. | G36: Debería cargar el número real, en función del otro filtrado | H36: Captura de pantalla 2026-05-18 123233.png | I36: Menor | J36: Randú
A37: =IF(C36="","","BUG-"&TEXT(ROW()-1,"000")) -> BUG-036 | B37: 46160 | C37: JZO | D37: CRM | E37: 1) Login como admin. 2) Acceder CRM. 3) Acceder a Leads. 4) Crear Lead. 5) Boton de + para añadir compañia. | F37: El boton de "Go back" no tiene funcionalidad de volver. | G37: Deberia poder volver a la pestaña anterior para más fluidez | H37: https://drive.google.com/file/d/1HIp9I1BWQZn2ajV6-FUJX5wxlTXJdZ1V/view?usp=drive_link | I37: Menor
A38: BUG-037 | B38: 46160 | C38: 46177 | D38: CRM | E38: 1)Login como admin 2)Acceder a CRM 3) Acceder a CRM 4)Acceder a lista) 5)Crear Lista | F38: No se muestra la lista que se creo recientemente en la sección de lista del Crm | G38: Debería poder enviar un correo a usuario correctamente | H38: https://drive.google.com/file/d/1eN1MuJPAPMxls8strEmhqkdKcgim8buQ/view?usp=sharing | I38: Menor
A39: =IF(C38="","","BUG-"&TEXT(ROW()-1,"000")) -> BUG-038 | B39: 46160 | C39: RGP | D39: Otra | E39: 1) Login como admin. 2) Acceder CRM. 3) Automation 4) Config | F39: Al entrar en config carga infinitamente | G39: Debería cargar la configuracion | H39: Captura de pantalla 2026-05-18 124147.png | I39: Bloqueante | J39: JUN06, JZO,Randú
A40: =IF(C39="","","BUG-"&TEXT(ROW()-1,"000")) -> BUG-039 | B40: 46160 | C40: 46179 | D40: Otra | E40: 1) Login como admin. 2) Acceder a crm 3) acceder a llistas . 4)Acceder a listas 5) acción -<enviar correo . | F40: al enviar un correo a un usuario, no se envia, y muestra un mensaje de error raro | G40: Debería poder envia un correo al usuario correctamente | H40: https://drive.google.com/file/d/1p18i2Ort671rvwqx3muUvPLLAhU__ISl/view?usp=drive_link | I40: Menor
...

Sheet Propuestas de mejora
A1: Las propuestas de mejora NO son bugs. Aquí va lo que "se podría hacer mejor". El PM las revisa después del piloto, no en sprint.
A2: ID | B2: Fecha | C2: Tester | D2: Área | E2: Propuesta | F2: Por qué la propones | G2: Prioridad sugerida | H2: Estado | I2: Notas del PM
A3: =IF(C2="","","MEJ-"&TEXT(ROW()-1,"000")) -> MEJ-002 | B3: 46156 | C3: 46175 | D3: CRM | E3: Indicar los campos obligatorios en las ventanas emergentes de creación o edición de datos, como la creación rápida de leads. | F3: Los usuarios deben de ser capaces de visualizar al momento que campos deben rellenar obligatoriamente | G3: Baja
A4: =IF(C3="","","MEJ-"&TEXT(ROW()-1,"000")) -> MEJ-003 | B4: 46156 | C4: 46176 | D4: CRM | E4: Eliminar el botón lateral izquierdo de acciones en la lista de leads, reemplazarlo con un botón de editar lead y añadir enlace en el identificador del lead para ver sus detalles | F4: El botón de acciones de lead es poco intuitivo y tiene el mismo nombre que otro elemento de la página, lo cual puede llevar a confusión. A demás, todos los apartados de vista se encuentran dentro de View Details, por lo que es inncesario crear varios botónes. | G4: Media
A5: =IF(C4="","","MEJ-"&TEXT(ROW()-1,"000")) -> MEJ-004 | B5: 46160 | C5: 46181 | D5: Calendario/Agenda | E5: Poder tener la función de agendar tareas en el calendario | F5: Para poder llevar al dia y tener cierto control y organización en las tareas a realizar. | G5: Baja
A6: =IF(C5="","","MEJ-"&TEXT(ROW()-1,"000")) -> MEJ-005 | B6: 46160 | C6: 46183 | D6: CRM | E6: Al crear un Schedule Automation, se podría crear dos opciones al presionar Save as template, que sea privado y público, y que no se dé por hecho que se sabe que se crea como privado, para evitar confusiones y queda más limpio. | F6: Al crear una automatización se podría confundir una persona si no sabe que salen privadas, por eso mejor crear dos opciones. | G6: Baja
A7: =IF(C6="","","MEJ-"&TEXT(ROW()-1,"000")) -> MEJ-006 | B7: 46160 | C7: 46177 | D7: CRM | E7: En la sección de media Library, en vez de poder permitir, que dos archivos tengan el mismo nombre con la misma extensión, se añada un identificador, como por ejemplo; archivo, archivo(1) | F7: Los nombres del archivo de un usuario, si tienen el mismo nombre, y con la misma extensión del archivo, podría darse el caso de que lleve a una confusión, a la hora de adjntar un archivo, de compartirlo o inciar una automatización, puede ocurrir con el archivo equivocado | G7: Baja
A8: =IF(C7="","","MEJ-"&TEXT(ROW()-1,"000")) -> MEJ-007 | B8: 46160 | C8: 46183 | D8: Otra | E8: En la sección Automation, Schedule Child Tasks podría ser una subsección de Schedule Tasks o que no salga como otra pestaña cuando está relacionado directamente, para que quede más limpio. | F8: Creo que quedaría más limpio dejaría menos margen a confusiones. | G8: Baja
A9: =IF(C8="","","MEJ-"&TEXT(ROW()-1,"000")) -> MEJ-008 | B9: 46160 | C9: 46175 | D9: Otra | E9: Crear un botón de creación rápida para las clínicas | F9: Al igual que se puede realizar una creación rápida de leads, las clínicas también tienen pocos cambios obligatorios, por lo que esto podría acelerar el flujo inicial de creación de clínicas y/o productos/clientes para ellas | G9: Media
A10: =IF(C9="","","MEJ-"&TEXT(ROW()-1,"000")) -> MEJ-009 | C10: RDC | D10: Crear paciente | E10: Añadir campo "Contacto del tutor/responsable legal" para pacientes menores de edad. Cuando el paciente tiene menos de 18 años (calculado por fecha de nacimiento), mostrar automáticamente campos opcionales: nombre del tutor, teléfono del tutor, email del tutor. Estos datos quedarían vinculados como contacto de emergencia/tutor, separados del email/teléfono del propio paciente. | F10: Actualmente para pacientes menores de edad no hay forma de registrar el contacto del padre/tutor de forma estructurada. Si se usa el email/teléfono del padre en los campos del paciente, el sistema los trata como datos del menor y además puede sobreescribir el registro del padre (BUG-036). Un paciente de 4 años no tiene email propio — el sistema debería contemplar este caso. | G10: Alta
A11: =IF(C10="","","MEJ-"&TEXT(ROW()-1,"000")) -> MEJ-010 | C11: RDC | D11: Crear doctor | E11: Añadir opción 'Medicina General' (u equivalente) en el selector de Medical Specialities, y/o hacer el campo obligatorio con un mensaje claro si se intenta guardar sin especialidad. Si el sistema permite médicos sin especialidad, mostrar un aviso tipo 'Este doctor no tendrá especialidad asignada y podría no aparecer en búsquedas de citas filtradas por especialidad'. | F11: Un doctor sin especialidad queda potencialmente inutilizable en el flujo de asignación de citas si ese flujo filtra por especialidad. Además, 'Medicina General' es la especialidad más común en atención primaria y debería estar disponible como opción. | G11: Alta
A12: =IF(C11="","","MEJ-"&TEXT(ROW()-1,"000")) -> MEJ-011 | C12: RDC | D12: Crear doctor | E12: Ampliar los campos obligatorios del formulario de alta de doctor para evitar fichas vacías en producción. Campos sugeridos como obligatorios: DNI/NIF (ver BUG-044), Medical Speciality (al menos una), Position/Title. Campos sugeridos como recomendados con aviso: Years of Experience, Qualifications, Medical Council. El progreso del formulario ya muestra '78% Complete' al rellenar solo los mínimos — ese indicador debería llegar al 100% solo cuando los datos clínicamente relevantes estén completos. | F12: Con los mínimos actuales (nombre + número de colegiado + email/teléfono) el doctor queda creado con Doctor ID placeholder, sin especialidad, sin horario y sin qualificaciones. Una ficha tan vacía no es útil para el flujo clínico real (asignación de citas, facturación, prescripciones). | G12: Alta
A13: =IF(C12="","","MEJ-"&TEXT(ROW()-1,"000")) -> MEJ-012 | C13: RDC | D13: Crear cita / Quick Appointment | E13: Añadir texto de ayuda o tooltip en el campo 'Notes for Doctor' del Step 3 que explique: (1) Dónde ve el médico la nota (agenda, ficha del paciente, notificación). (2) Cuándo la recibe. (3) Si se puede editar después de confirmar la cita. Adicionalmente, mostrar en la ficha de la cita confirmada las notas introducidas, para que el admin pueda verificar que llegaron correctamente. | F13: El campo es obligatorio pero su propósito y destino son opacos. El personal administrativo no puede saber si su mensaje llega al médico ni cómo. En producción esto genera desconfianza en el sistema y workarounds (llamadas telefónicas, WhatsApp). | G13: Media
A16: =IF(C15="","","MEJ-"&TEXT(ROW()-1,"000"))
A17: =IF(C16="","","MEJ-"&TEXT(ROW()-1,"000"))
A18: =IF(C17="","","MEJ-"&TEXT(ROW()-1,"000"))
A19: =IF(C18="","","MEJ-"&TEXT(ROW()-1,"000"))
A20: =IF(C19="","","MEJ-"&TEXT(ROW()-1,"000"))
A21: =IF(C20="","","MEJ-"&TEXT(ROW()-1,"000"))
A22: =IF(C21="","","MEJ-"&TEXT(ROW()-1,"000"))
A23: =IF(C22="","","MEJ-"&TEXT(ROW()-1,"000"))
A24: =IF(C23="","","MEJ-"&TEXT(ROW()-1,"000"))
A25: =IF(C24="","","MEJ-"&TEXT(ROW()-1,"000"))
A26: =IF(C25="","","MEJ-"&TEXT(ROW()-1,"000"))
A27: =IF(C26="","","MEJ-"&TEXT(ROW()-1,"000"))
... A302: =IF(C301="","","MEJ-"&TEXT(ROW()-1,"000"))

Sheet Plan de testing
B1: Plan de testing por semana
B4: Semana | C4: Áreas a probar | D4: Foco / instrucciones
B5: Semana 1 | C5: Crear paciente • Crear doctor • Calendario/Agenda • Citas (admin) | D5: Romper el alta de pacientes y doctores. Probar datos inválidos, vacíos, duplicados, caracteres raros. Crear citas en huecos ocupados, en huecos libres, en pasado, en futuro lejano.Investigar el proceso entero de creación y explorar las vías que se permiten.
B6: Semana 2 | C6: Sales orders / Facturación • Retell • CRM | D6: Foco principal: facturación end-to-end. Casos: paciente particular, paciente con mutua, varios servicios añadidos en consulta, anulación de factura, división de pagos. Atacar especialmente la duplicación de importes. Retell: revisar que la grabación del webhook es coherente con la llamada real.
B7: Semana 3 | C7: Historia clínica + IA • Servicios • XLS uploads/Mapping | D7: IA: probar dictados largos, cortos, con interrupciones, con varios hablantes, en silencio. Verificar que la historia clínica generada es coherente. Servicios y XLS: subir XLS con encabezados raros, datos faltantes, formatos numéricos distintos, símbolos.
B8: Semana 4 | C8: Cancel automation • Web pública • Retesteo de bugs verificados | D8: Cancel automation: ejecutar sobre lotes de varias citas a la vez, verificar que cada paciente recibe solo una notificación, no varias. Web: revisar que botones llevan a donde deben, formulario de cita funciona. Resto del tiempo: reverificar bugs marcados como Arreglado.
B11: Asignación sugerida (PM define)
B12: El PM puede dividir los 20 juniors en grupos de 4-5 por área cada semana. Rotar entre semanas. No dejar a un mismo junior siempre en la misma área (la familiaridad mata el testing exploratorio).

Sheet Resumen
B1: Resumen para el PM
B3: Por feature | H3: Por estado
B4: Feature | C4: Total | D4: Bloqueantes | E4: Graves | F4: Abiertos | H4: Estado | I4: Count
B5: Crear paciente | C5: =COUNTIF(Bugs!D:D,B5) -> 17 | D5: =COUNTIFS(Bugs!D:D,B5,Bugs!K:K,"Bloqueante") -> 0 | E5: =COUNTIFS(Bugs!D:D,B5,Bugs!K:K,"Grave") -> 0 | F5: =COUNTIFS(Bugs!D:D,B5,Bugs!L:L,"<>Arreglado",Bugs!L:L,"<>Verificado",Bugs!L:L,"<>No es bug",Bugs!L:L,"<>Duplicado",Bugs!L:L,"<>Diferido") -> 16 | H5: Nuevo | I5: =COUNTIF(Bugs!L:L,H5) -> 0
B6: Crear doctor | C6: =COUNTIF(Bugs!D:D,B6) -> 8 | D6: =COUNTIFS(Bugs!D:D,B6,Bugs!K:K,"Bloqueante") -> 0 | E6: =COUNTIFS(Bugs!D:D,B6,Bugs!K:K,"Grave") -> 0 | F6: =COUNTIFS(Bugs!D:D,B6,Bugs!L:L,"<>Arreglado",Bugs!L:L,"<>Verificado",Bugs!L:L,"<>No es bug",Bugs!L:L,"<>Duplicado",Bugs!L:L,"<>Diferido") -> 8 | H6: En revisión | I6: =COUNTIF(Bugs!L:L,H6) -> 1
B7: Calendario/Agenda | C7: =COUNTIF(Bugs!D:D,B7) -> 2 | D7: =COUNTIFS(Bugs!D:D,B7,Bugs!K:K,"Bloqueante") -> 0 | E7: =COUNTIFS(Bugs!D:D,B7,Bugs!K:K,"Grave") -> 0 | F7: =COUNTIFS(Bugs!D:D,B7,Bugs!L:L,"<>Arreglado",Bugs!L:L,"<>Verificado",Bugs!L:L,"<>No es bug",Bugs!L:L,"<>Duplicado",Bugs!L:L,"<>Diferido") -> 2 | H7: En arreglo | I7: =COUNTIF(Bugs!L:L,H7) -> 4
B8: Citas (admin) | C8: =COUNTIF(Bugs!D:D,B8) -> 7 | D8: =COUNTIFS(Bugs!D:D,B8,Bugs!K:K,"Bloqueante") -> 0 | E8: =COUNTIFS(Bugs!D:D,B8,Bugs!K:K,"Grave") -> 0 | F8: =COUNTIFS(Bugs!D:D,B8,Bugs!L:L,"<>Arreglado",Bugs!L:L,"<>Verificado",Bugs!L:L,"<>No es bug",Bugs!L:L,"<>Duplicado",Bugs!L:L,"<>Diferido") -> 7 | H8: Arreglado | I8: =COUNTIF(Bugs!L:L,H8) -> 1
B9: Retell - llamadas IA | C9: =COUNTIF(Bugs!D:D,B9) -> 0 | D9: =COUNTIFS(Bugs!D:D,B9,Bugs!K:K,"Bloqueante") -> 0 | E9: =COUNTIFS(Bugs!D:D,B9,Bugs!K:K,"Grave") -> 0 | F9: =COUNTIFS(Bugs!D:D,B9,Bugs!L:L,"<>Arreglado",Bugs!L:L,"<>Verificado",Bugs!L:L,"<>No es bug",Bugs!L:L,"<>Duplicado",Bugs!L:L,"<>Diferido") -> 0 | H9: Verificado | I9: =COUNTIF(Bugs!L:L,H9) -> 2
B10: CRM | C10: =COUNTIF(Bugs!D:D,B10) -> 27 | D10: =COUNTIFS(Bugs!D:D,B10,Bugs!K:K,"Bloqueante") -> 5 | E10: =COUNTIFS(Bugs!D:D,B10,Bugs!K:K,"Grave") -> 0 | F10: =COUNTIFS(Bugs!D:D,B10,Bugs!L:L,"<>Arreglado",Bugs!L:L,"<>Verificado",Bugs!L:L,"<>No es bug",Bugs!L:L,"<>Duplicado",Bugs!L:L,"<>Diferido") -> 18 | H10: Duplicado | I10: =COUNTIF(Bugs!L:L,H10) -> 0
B11: Historia clínica + IA | C11: =COUNTIF(Bugs!D:D,B11) -> 0 | D11: =COUNTIFS(Bugs!D:D,B11,Bugs!K:K,"Bloqueante") -> 0 | E11: =COUNTIFS(Bugs!D:D,B11,Bugs!K:K,"Grave") -> 0 | F11: =COUNTIFS(Bugs!D:D,B11,Bugs!L:L,"<>Arreglado",Bugs!L:L,"<>Verificado",Bugs!L:L,"<>No es bug",Bugs!L:L,"<>Duplicado",Bugs!L:L,"<>Diferido") -> 0 | H11: No es bug | I11: =COUNTIF(Bugs!L:L,H11) -> 4
B12: Servicios | C12: =COUNTIF(Bugs!D:D,B12) -> 2 | D12: =COUNTIFS(Bugs!D:D,B12,Bugs!K:K,"Bloqueante") -> 0 | E12: =COUNTIFS(Bugs!D:D,B12,Bugs!K:K,"Grave") -> 0 | F12: =COUNTIFS(Bugs!D:D,B12,Bugs!L:L,"<>Arreglado",Bugs!L:L,"<>Verificado",Bugs!L:L,"<>No es bug",Bugs!L:L,"<>Duplicado",Bugs!L:L,"<>Diferido") -> 2 | H12: Diferido | I12: =COUNTIF(Bugs!L:L,H12) -> 4
B13: Sales orders/Facturación | C13: =COUNTIF(Bugs!D:D,B13) -> 1 | D13: =COUNTIFS(Bugs!D:D,B13,Bugs!K:K,"Bloqueante") -> 1 | E13: =COUNTIFS(Bugs!D:D,B13,Bugs!K:K,"Grave") -> 0 | F13: =COUNTIFS(Bugs!D:D,B13,Bugs!L:L,"<>Arreglado",Bugs!L:L,"<>Verificado",Bugs!L:L,"<>No es bug",Bugs!L:L,"<>Duplicado",Bugs!L:L,"<>Diferido") -> 0 | H13: Reabierto | I13: =COUNTIF(Bugs!L:L,H13) -> 0
B14: XLS uploads/Mapping | C14: =COUNTIF(Bugs!D:D,B14) -> 0 | D14: =COUNTIFS(Bugs!D:D,B14,Bugs!K:K,"Bloqueante") -> 0 | E14: =COUNTIFS(Bugs!D:D,B14,Bugs!K:K,"Grave") -> 0 | F14: =COUNTIFS(Bugs!D:D,B14,Bugs!L:L,"<>Arreglado",Bugs!L:L,"<>Verificado",Bugs!L:L,"<>No es bug",Bugs!L:L,"<>Duplicado",Bugs!L:L,"<>Diferido") -> 0
B15: Cancel automation | C15: =COUNTIF(Bugs!D:D,B15) -> 0 | D15: =COUNTIFS(Bugs!D:D,B15,Bugs!K:K,"Bloqueante") -> 0 | E15: =COUNTIFS(Bugs!D:D,B15,Bugs!K:K,"Grave") -> 0 | F15: =COUNTIFS(Bugs!D:D,B15,Bugs!L:L,"<>Arreglado",Bugs!L:L,"<>Verificado",Bugs!L:L,"<>No es bug",Bugs!L:L,"<>Duplicado",Bugs!L:L,"<>Diferido") -> 0
B16: Web pública | C16: =COUNTIF(Bugs!D:D,B16) -> 0 | D16: =COUNTIFS(Bugs!D:D,B16,Bugs!K:K,"Bloqueante") -> 0 | E16: =COUNTIFS(Bugs!D:D,B16,Bugs!K:K,"Grave") -> 0 | F16: =COUNTIFS(Bugs!D:D,B16,Bugs!L:L,"<>Arreglado",Bugs!L:L,"<>Verificado",Bugs!L:L,"<>No es bug",Bugs!L:L,"<>Duplicado",Bugs!L:L,"<>Diferido") -> 0
B17: Otra | C17: =COUNTIF(Bugs!D:D,B17) -> 33 | D17: =COUNTIFS(Bugs!D:D,B17,Bugs!K:K,"Bloqueante") -> 0 | E17: =COUNTIFS(Bugs!D:D,B17,Bugs!K:K,"Grave") -> 0 | F17: =COUNTIFS(Bugs!D:D,B17,Bugs!L:L,"<>Arreglado",Bugs!L:L,"<>Verificado",Bugs!L:L,"<>No es bug",Bugs!L:L,"<>Duplicado",Bugs!L:L,"<>Diferido") -> 33
B18: TOTAL | C18: =SUM(C5:C17) -> 97 | D18: =SUM(D5:D17) -> 6 | E18: =SUM(E5:E17) -> 0 | F18: =SUM(F5:F17) -> 86
B22: Por tester (cuántos bugs ha reportado cada uno)
B23: Nombre | C23: Tester | D23: Bugs reportados
B24: Ejemplo | C24: JUN01 | D24: =COUNTIF(Bugs!C:C,C24) -> 1
B25: Daniel Martínez Torres | C25: DMT | D25: =COUNTIF(Bugs!C:C,C25) -> 28
B26: Randú Condori | C26: JUN03 | D26: =COUNTIF(Bugs!C:C,C26) -> 0
B27: Cristian Lalalangui | C27: JUN04 | D27: =COUNTIF(Bugs!C:C,C27) -> 0
B28: Felipe Parra Ramírez | C28: JUN05 | D28: =COUNTIF(Bugs!C:C,C28) -> 0
B29: Isamir Valencia López | C29: JUN06 | D29: =COUNTIF(Bugs!C:C,C29) -> 0
B30: Sara Estenos | C30: JUN07 | D30: =COUNTIF(Bugs!C:C,C30) -> 0
B31: Josué Zapata Ortiz | C31: JZO | D31: =COUNTIF(Bugs!C:C,C31) -> 8
B32: Diana Carolina Pita Amador | C32: JUN09 | D32: =COUNTIF(Bugs!C:C,C32) -> 0
B33: Rodrigo García Pérez | C33: RGP | D33: =COUNTIF(Bugs!C:C,C33) -> 9
B34: Josue David Real | C34: JUN11 | D34: 5
B35: Antonio Mba | C35: JUN12 | D35: =COUNTIF(Bugs!C:C,C35) -> 23
C36: JUN13 | D36: =COUNTIF(Bugs!C:C,C36) -> 0
C37: JUN14 | D37: =COUNTIF(Bugs!C:C,C37) -> 0
C38: JUN15 | D38: =COUNTIF(Bugs!C:C,C38) -> 0
C39: JUN16 | D39: =COUNTIF(Bugs!C:C,C39) -> 0
C40: JUN17 | D40: =COUNTIF(Bugs!C:C,C40) -> 0
C41: JUN18 | D41: =COUNTIF(Bugs!C:C,C41) -> 0
C42: JUN19 | D42: =COUNTIF(Bugs!C:C,C42) -> 0
C43: JUN20 | D43: =COUNTIF(Bugs!C:C,C43) -> 0

Sheet Funcionalidades
A1: # | B1: Functionality
A2: Create patient | B2: Having a user with patient role, which can be assigned to a consultation, has a medical history, can be billed an activity, can register it's own consultations
A3: Create doctor | B3: Having a user with doctor role which can have patients assigned, create and modify their medical histories, bill activities, manage his calendar,...
A4: Clinical calendar / agenda | B4: Create availability slots, monthly, weekly, daily views, click-on registers, shows KPIs, has clinic view (every doctor), doctor view(its own registers)
A5: Appointment creation by admin | B5: For every available slot, an admin can create a consultation for a patient
A6: Appointment creation by patient online in web | B6: Each patient can register and create a doctors appointment
A7: Retell | B7: We have a Retell infrastructure, we have outcoming and incoming calls by AI agents and register those with a webhook connection to Retell
A8: CRM | B8: Regular CRM with leads and contacts, we have a function that brings AI suggestions of upselling based on user history with us
A9: Clinical history with AI functions | B9: Doctor takes notes speaking and we generate the clinic history of that appointment, suggest add-ons, etc
A10: Services catalogue | B10: Create as products the different type of appointments, each with it's own duration, price, tags, doctors
A11: Sales order and invoices | B11: When a consultation is efectuated, the patient has to be billed for the service of the consult + if there are any other services that have been added during the consultation, this generates a billable order and an invoice, depending on the patient will be billed to patient or insurance company
A12: XLS uploads with active mapping | B12: in case we want to migrate a clinic database to our system, in case we need to update the prices of services from a insurance company, for this we have a mapping system where we connect xls headers to our systems ones
... A14: Cuidarles web | B14: Finish the design of the web, make everything functional
